<?xml version="1.0" ?>
<!-- =================================================================================== -->
<!-- |    This document was autogenerated by xacro from /home/hex/ros2_ws/src/hapthexa_description/urdf/hapthexa.xacro | -->
<!-- |    EDITING THIS FILE BY HAND IS NOT RECOMMENDED                                 | -->
<!-- =================================================================================== -->
<robot name="hapthexa">
  <material name="silver_default">
    <color rgba="0.700 0.700 0.700 1.000"/>
  </material>
  <material name="opaque555">
    <color rgba="0.0196078431372549 0.0196078431372549 0.0196078431372549 1.0"/>
  </material>
  <material name="_">
    <color rgba="0.6274509803921569 0.6274509803921569 0.6274509803921569 1.0"/>
  </material>
  <transmission name="rev1_tran">
    <type>transmission_interface/SimpleTransmission</type>
    <joint name="rev1">
      <hardwareInterface>hardware_interface/EffortJointInterface</hardwareInterface>
    </joint>
    <actuator name="rev1_actr">
      <hardwareInterface>hardware_interface/EffortJointInterface</hardwareInterface>
      <mechanicalReduction>1</mechanicalReduction>
    </actuator>
  </transmission>
  <transmission name="rev2_tran">
    <type>transmission_interface/SimpleTransmission</type>
    <joint name="rev2">
      <hardwareInterface>hardware_interface/EffortJointInterface</hardwareInterface>
    </joint>
    <actuator name="rev2_actr">
      <hardwareInterface>hardware_interface/EffortJointInterface</hardwareInterface>
      <mechanicalReduction>1</mechanicalReduction>
    </actuator>
  </transmission>
  <transmission name="rev3_tran">
    <type>transmission_interface/SimpleTransmission</type>
    <joint name="rev3">
      <hardwareInterface>hardware_interface/EffortJointInterface</hardwareInterface>
    </joint>
    <actuator name="rev3_actr">
      <hardwareInterface>hardware_interface/EffortJointInterface</hardwareInterface>
      <mechanicalReduction>1</mechanicalReduction>
    </actuator>
  </transmission>
  <transmission name="rev4_tran">
    <type>transmission_interface/SimpleTransmission</type>
    <joint name="rev4">
      <hardwareInterface>hardware_interface/EffortJointInterface</hardwareInterface>
    </joint>
    <actuator name="rev4_actr">
      <hardwareInterface>hardware_interface/EffortJointInterface</hardwareInterface>
      <mechanicalReduction>1</mechanicalReduction>
    </actuator>
  </transmission>
  <transmission name="rev5_tran">
    <type>transmission_interface/SimpleTransmission</type>
    <joint name="rev5">
      <hardwareInterface>hardware_interface/EffortJointInterface</hardwareInterface>
    </joint>
    <actuator name="rev5_actr">
      <hardwareInterface>hardware_interface/EffortJointInterface</hardwareInterface>
      <mechanicalReduction>1</mechanicalReduction>
    </actuator>
  </transmission>
  <transmission name="rev6_tran">
    <type>transmission_interface/SimpleTransmission</type>
    <joint name="rev6">
      <hardwareInterface>hardware_interface/EffortJointInterface</hardwareInterface>
    </joint>
    <actuator name="rev6_actr">
      <hardwareInterface>hardware_interface/EffortJointInterface</hardwareInterface>
      <mechanicalReduction>1</mechanicalReduction>
    </actuator>
  </transmission>
  <transmission name="rev7_tran">
    <type>transmission_interface/SimpleTransmission</type>
    <joint name="rev7">
      <hardwareInterface>hardware_interface/EffortJointInterface</hardwareInterface>
    </joint>
    <actuator name="rev7_actr">
      <hardwareInterface>hardware_interface/EffortJointInterface</hardwareInterface>
      <mechanicalReduction>1</mechanicalReduction>
    </actuator>
  </transmission>
  <transmission name="rev8_tran">
    <type>transmission_interface/SimpleTransmission</type>
    <joint name="rev8">
      <hardwareInterface>hardware_interface/EffortJointInterface</hardwareInterface>
    </joint>
    <actuator name="rev8_actr">
      <hardwareInterface>hardware_interface/EffortJointInterface</hardwareInterface>
      <mechanicalReduction>1</mechanicalReduction>
    </actuator>
  </transmission>
  <transmission name="rev9_tran">
    <type>transmission_interface/SimpleTransmission</type>
    <joint name="rev9">
      <hardwareInterface>hardware_interface/EffortJointInterface</hardwareInterface>
    </joint>
    <actuator name="rev9_actr">
      <hardwareInterface>hardware_interface/EffortJointInterface</hardwareInterface>
      <mechanicalReduction>1</mechanicalReduction>
    </actuator>
  </transmission>
  <transmission name="rev10_tran">
    <type>transmission_interface/SimpleTransmission</type>
    <joint name="rev10">
      <hardwareInterface>hardware_interface/EffortJointInterface</hardwareInterface>
    </joint>
    <actuator name="rev10_actr">
      <hardwareInterface>hardware_interface/EffortJointInterface</hardwareInterface>
      <mechanicalReduction>1</mechanicalReduction>
    </actuator>
  </transmission>
  <transmission name="rev11_tran">
    <type>transmission_interface/SimpleTransmission</type>
    <joint name="rev11">
      <hardwareInterface>hardware_interface/EffortJointInterface</hardwareInterface>
    </joint>
    <actuator name="rev11_actr">
      <hardwareInterface>hardware_interface/EffortJointInterface</hardwareInterface>
      <mechanicalReduction>1</mechanicalReduction>
    </actuator>
  </transmission>
  <transmission name="rev12_tran">
    <type>transmission_interface/SimpleTransmission</type>
    <joint name="rev12">
      <hardwareInterface>hardware_interface/EffortJointInterface</hardwareInterface>
    </joint>
    <actuator name="rev12_actr">
      <hardwareInterface>hardware_interface/EffortJointInterface</hardwareInterface>
      <mechanicalReduction>1</mechanicalReduction>
    </actuator>
  </transmission>
  <transmission name="rev13_tran">
    <type>transmission_interface/SimpleTransmission</type>
    <joint name="rev13">
      <hardwareInterface>hardware_interface/EffortJointInterface</hardwareInterface>
    </joint>
    <actuator name="rev13_actr">
      <hardwareInterface>hardware_interface/EffortJointInterface</hardwareInterface>
      <mechanicalReduction>1</mechanicalReduction>
    </actuator>
  </transmission>
  <transmission name="rev14_tran">
    <type>transmission_interface/SimpleTransmission</type>
    <joint name="rev14">
      <hardwareInterface>hardware_interface/EffortJointInterface</hardwareInterface>
    </joint>
    <actuator name="rev14_actr">
      <hardwareInterface>hardware_interface/EffortJointInterface</hardwareInterface>
      <mechanicalReduction>1</mechanicalReduction>
    </actuator>
  </transmission>
  <transmission name="rev15_tran">
    <type>transmission_interface/SimpleTransmission</type>
    <joint name="rev15">
      <hardwareInterface>hardware_interface/EffortJointInterface</hardwareInterface>
    </joint>
    <actuator name="rev15_actr">
      <hardwareInterface>hardware_interface/EffortJointInterface</hardwareInterface>
      <mechanicalReduction>1</mechanicalReduction>
    </actuator>
  </transmission>
  <transmission name="rev16_tran">
    <type>transmission_interface/SimpleTransmission</type>
    <joint name="rev16">
      <hardwareInterface>hardware_interface/EffortJointInterface</hardwareInterface>
    </joint>
    <actuator name="rev16_actr">
      <hardwareInterface>hardware_interface/EffortJointInterface</hardwareInterface>
      <mechanicalReduction>1</mechanicalReduction>
    </actuator>
  </transmission>
  <transmission name="rev17_tran">
    <type>transmission_interface/SimpleTransmission</type>
    <joint name="rev17">
      <hardwareInterface>hardware_interface/EffortJointInterface</hardwareInterface>
    </joint>
    <actuator name="rev17_actr">
      <hardwareInterface>hardware_interface/EffortJointInterface</hardwareInterface>
      <mechanicalReduction>1</mechanicalReduction>
    </actuator>
  </transmission>
  <transmission name="rev18_tran">
    <type>transmission_interface/SimpleTransmission</type>
    <joint name="rev18">
      <hardwareInterface>hardware_interface/EffortJointInterface</hardwareInterface>
    </joint>
    <actuator name="rev18_actr">
      <hardwareInterface>hardware_interface/EffortJointInterface</hardwareInterface>
      <mechanicalReduction>1</mechanicalReduction>
    </actuator>
  </transmission>
  <link name="base_link">
    <inertial>
      <origin rpy="0 0 0" xyz="-0.023482686234529128 0.009399208569724241 -0.030381180045183934"/>
      <mass value="0.5111070184633425"/>
      <inertia ixx="0.001015" ixy="3e-06" ixz="-3e-06" iyy="0.001772" iyz="-1e-06" izz="0.000909"/>
    </inertial>
    <visual>
      <origin rpy="0 0 0" xyz="0 0 0"/>
      <geometry>
        <mesh filename="package://hapthexa_description/meshes/base_link.stl" scale="0.001 0.001 0.001"/>
      </geometry>
      <material name="opaque555"/>
    </visual>
    <collision>
      <origin rpy="0 0 0" xyz="0 0 0"/>
      <geometry>
        <mesh filename="package://hapthexa_description/meshes/base_link.stl" scale="0.001 0.001 0.001"/>
      </geometry>
    </collision>
  </link>
  <link name="_Coxa__4__1">
    <inertial>
      <origin rpy="0 0 0" xyz="0.019504685340380374 -0.012341676148518561 -0.03452353861717494"/>
      <mass value="0.050011908854628584"/>
      <inertia ixx="1.5e-05" ixy="-0.0" ixz="0.0" iyy="1.1e-05" iyz="0.0" izz="1.5e-05"/>
    </inertial>
    <visual>
      <origin rpy="0 0 0" xyz="-0.016517 -0.026286 0.099741"/>
      <geometry>
        <mesh filename="package://hapthexa_description/meshes/_Coxa__4__1.stl" scale="0.001 0.001 0.001"/>
      </geometry>
      <material name="_"/>
    </visual>
    <collision>
      <origin rpy="0 0 0" xyz="-0.016517 -0.026286 0.099741"/>
      <geometry>
        <mesh filename="package://hapthexa_description/meshes/_Coxa__4__1.stl" scale="0.001 0.001 0.001"/>
      </geometry>
    </collision>
  </link>
  <link name="_Coxa__2__1">
    <inertial>
      <origin rpy="0 0 0" xyz="0.039650915389736474 -0.012341676148518515 -0.0003698293133218289"/>
      <mass value="0.050011908854628584"/>
      <inertia ixx="1.5e-05" ixy="-0.0" ixz="0.0" iyy="1.1e-05" iyz="-0.0" izz="1.5e-05"/>
    </inertial>
    <visual>
      <origin rpy="0 0 0" xyz="-0.056517 -0.026286 0.030459"/>
      <geometry>
        <mesh filename="package://hapthexa_description/meshes/_Coxa__2__1.stl" scale="0.001 0.001 0.001"/>
      </geometry>
      <material name="_"/>
    </visual>
    <collision>
      <origin rpy="0 0 0" xyz="-0.056517 -0.026286 0.030459"/>
      <geometry>
        <mesh filename="package://hapthexa_description/meshes/_Coxa__2__1.stl" scale="0.001 0.001 0.001"/>
      </geometry>
    </collision>
  </link>
  <link name="_Coxa__1__1">
    <inertial>
      <origin rpy="0 0 0" xyz="0.020283607961812552 -0.012341676148510491 0.03407168985837998"/>
      <mass value="0.050011908854628584"/>
      <inertia ixx="1.5e-05" ixy="-0.0" ixz="-0.0" iyy="1.1e-05" iyz="-0.0" izz="1.5e-05"/>
    </inertial>
    <visual>
      <origin rpy="0 0 0" xyz="-0.016517 -0.026286 -0.038824"/>
      <geometry>
        <mesh filename="package://hapthexa_description/meshes/_Coxa__1__1.stl" scale="0.001 0.001 0.001"/>
      </geometry>
      <material name="_"/>
    </visual>
    <collision>
      <origin rpy="0 0 0" xyz="-0.016517 -0.026286 -0.038824"/>
      <geometry>
        <mesh filename="package://hapthexa_description/meshes/_Coxa__1__1.stl" scale="0.001 0.001 0.001"/>
      </geometry>
    </collision>
  </link>
  <link name="_Coxa_1">
    <inertial>
      <origin rpy="0 0 0" xyz="-0.019504988441448892 -0.012439675760187565 0.03452349701588872"/>
      <mass value="0.050011908854628584"/>
      <inertia ixx="1.5e-05" ixy="0.0" ixz="0.0" iyy="1.1e-05" iyz="-0.0" izz="1.5e-05"/>
    </inertial>
    <visual>
      <origin rpy="0 0 0" xyz="0.063483 -0.026286 -0.038824"/>
      <geometry>
        <mesh filename="package://hapthexa_description/meshes/_Coxa_1.stl" scale="0.001 0.001 0.001"/>
      </geometry>
      <material name="_"/>
    </visual>
    <collision>
      <origin rpy="0 0 0" xyz="0.063483 -0.026286 -0.038824"/>
      <geometry>
        <mesh filename="package://hapthexa_description/meshes/_Coxa_1.stl" scale="0.001 0.001 0.001"/>
      </geometry>
    </collision>
  </link>
  <link name="_Coxa__5__1">
    <inertial>
      <origin rpy="0 0 0" xyz="-0.039651218490817194 -0.012341676148518447 0.0003707877120360213"/>
      <mass value="0.050011908854628584"/>
      <inertia ixx="1.5e-05" ixy="0.0" ixz="0.0" iyy="1.1e-05" iyz="0.0" izz="1.5e-05"/>
    </inertial>
    <visual>
      <origin rpy="0 0 0" xyz="0.103483 -0.026286 0.030459"/>
      <geometry>
        <mesh filename="package://hapthexa_description/meshes/_Coxa__5__1.stl" scale="0.001 0.001 0.001"/>
      </geometry>
      <material name="_"/>
    </visual>
    <collision>
      <origin rpy="0 0 0" xyz="0.103483 -0.026286 0.030459"/>
      <geometry>
        <mesh filename="package://hapthexa_description/meshes/_Coxa__5__1.stl" scale="0.001 0.001 0.001"/>
      </geometry>
    </collision>
  </link>
  <link name="_Coxa__3__1">
    <inertial>
      <origin rpy="0 0 0" xyz="-0.020146381599897206 -0.01234167614851837 -0.034153230104497306"/>
      <mass value="0.050011908854628584"/>
      <inertia ixx="1.5e-05" ixy="0.0" ixz="-0.0" iyy="1.1e-05" iyz="0.0" izz="1.5e-05"/>
    </inertial>
    <visual>
      <origin rpy="0 0 0" xyz="0.063483 -0.026286 0.099741"/>
      <geometry>
        <mesh filename="package://hapthexa_description/meshes/_Coxa__3__1.stl" scale="0.001 0.001 0.001"/>
      </geometry>
      <material name="_"/>
    </visual>
    <collision>
      <origin rpy="0 0 0" xyz="0.063483 -0.026286 0.099741"/>
      <geometry>
        <mesh filename="package://hapthexa_description/meshes/_Coxa__3__1.stl" scale="0.001 0.001 0.001"/>
      </geometry>
    </collision>
  </link>
  <link name="_Femur__1__1">
    <inertial>
      <origin rpy="0 0 0" xyz="0.0415906312765175 0.010989309598100948 0.03363429654287885"/>
      <mass value="0.02302342374104796"/>
      <inertia ixx="9e-06" ixy="-0.0" ixz="-2e-06" iyy="1.4e-05" iyz="-0.0" izz="7e-06"/>
    </inertial>
    <visual>
      <origin rpy="0 0 0" xyz="-0.02142 -0.002786 -0.084577"/>
      <geometry>
        <mesh filename="package://hapthexa_description/meshes/_Femur__1__1.stl" scale="0.001 0.001 0.001"/>
      </geometry>
      <material name="_"/>
    </visual>
    <collision>
      <origin rpy="0 0 0" xyz="-0.02142 -0.002786 -0.084577"/>
      <geometry>
        <mesh filename="package://hapthexa_description/meshes/_Femur__1__1.stl" scale="0.001 0.001 0.001"/>
      </geometry>
    </collision>
  </link>
  <link name="_Femur_1">
    <inertial>
      <origin rpy="0 0 0" xyz="-0.008546088557166681 0.01098930959810179 0.052801094546086225"/>
      <mass value="0.02302342374104796"/>
      <inertia ixx="9e-06" ixy="0.0" ixz="2e-06" iyy="1.4e-05" iyz="-0.0" izz="7e-06"/>
    </inertial>
    <visual>
      <origin rpy="0 0 0" xyz="0.100764 -0.002686 -0.065797"/>
      <geometry>
        <mesh filename="package://hapthexa_description/meshes/_Femur_1.stl" scale="0.001 0.001 0.001"/>
      </geometry>
      <material name="_"/>
    </visual>
    <collision>
      <origin rpy="0 0 0" xyz="0.100764 -0.002686 -0.065797"/>
      <geometry>
        <mesh filename="package://hapthexa_description/meshes/_Femur_1.stl" scale="0.001 0.001 0.001"/>
      </geometry>
    </collision>
  </link>
  <link name="_Femur__5__1">
    <inertial>
      <origin rpy="0 0 0" xyz="-0.05000043554625219 0.010989309598091091 0.01900047909596079"/>
      <mass value="0.02302342374104796"/>
      <inertia ixx="5e-06" ixy="0.0" ixz="0.0" iyy="1.4e-05" iyz="0.0" izz="1e-05"/>
    </inertial>
    <visual>
      <origin rpy="0 0 0" xyz="0.145483 -0.002786 0.049259"/>
      <geometry>
        <mesh filename="package://hapthexa_description/meshes/_Femur__5__1.stl" scale="0.001 0.001 0.001"/>
      </geometry>
      <material name="_"/>
    </visual>
    <collision>
      <origin rpy="0 0 0" xyz="0.145483 -0.002786 0.049259"/>
      <geometry>
        <mesh filename="package://hapthexa_description/meshes/_Femur__5__1.stl" scale="0.001 0.001 0.001"/>
      </geometry>
    </collision>
  </link>
  <link name="_Femur__3__1">
    <inertial>
      <origin rpy="0 0 0" xyz="-0.0414544985396066 0.010989309598090703 -0.033801136250771024"/>
      <mass value="0.02302342374104796"/>
      <inertia ixx="9e-06" ixy="0.0" ixz="-2e-06" iyy="1.4e-05" iyz="0.0" izz="7e-06"/>
    </inertial>
    <visual>
      <origin rpy="0 0 0" xyz="0.068202 -0.002786 0.145514"/>
      <geometry>
        <mesh filename="package://hapthexa_description/meshes/_Femur__3__1.stl" scale="0.001 0.001 0.001"/>
      </geometry>
      <material name="_"/>
    </visual>
    <collision>
      <origin rpy="0 0 0" xyz="0.068202 -0.002786 0.145514"/>
      <geometry>
        <mesh filename="package://hapthexa_description/meshes/_Femur__3__1.stl" scale="0.001 0.001 0.001"/>
      </geometry>
    </collision>
  </link>
  <link name="_Femur__4__1">
    <inertial>
      <origin rpy="0 0 0" xyz="0.008545785456105369 0.01098930959808993 -0.05280113614736581"/>
      <mass value="0.02302342374104796"/>
      <inertia ixx="9e-06" ixy="-0.0" ixz="2e-06" iyy="1.4e-05" iyz="0.0" izz="7e-06"/>
    </inertial>
    <visual>
      <origin rpy="0 0 0" xyz="-0.053798 -0.002786 0.126714"/>
      <geometry>
        <mesh filename="package://hapthexa_description/meshes/_Femur__4__1.stl" scale="0.001 0.001 0.001"/>
      </geometry>
      <material name="_"/>
    </visual>
    <collision>
      <origin rpy="0 0 0" xyz="-0.053798 -0.002786 0.126714"/>
      <geometry>
        <mesh filename="package://hapthexa_description/meshes/_Femur__4__1.stl" scale="0.001 0.001 0.001"/>
      </geometry>
    </collision>
  </link>
  <link name="_Femur__2__1">
    <inertial>
      <origin rpy="0 0 0" xyz="0.05000013244517007 0.010989309598089504 -0.018999520697242166"/>
      <mass value="0.02302342374104796"/>
      <inertia ixx="5e-06" ixy="-0.0" ixz="0.0" iyy="1.4e-05" iyz="-0.0" izz="1e-05"/>
    </inertial>
    <visual>
      <origin rpy="0 0 0" xyz="-0.098517 -0.002786 0.011659"/>
      <geometry>
        <mesh filename="package://hapthexa_description/meshes/_Femur__2__1.stl" scale="0.001 0.001 0.001"/>
      </geometry>
      <material name="_"/>
    </visual>
    <collision>
      <origin rpy="0 0 0" xyz="-0.098517 -0.002786 0.011659"/>
      <geometry>
        <mesh filename="package://hapthexa_description/meshes/_Femur__2__1.stl" scale="0.001 0.001 0.001"/>
      </geometry>
    </collision>
  </link>
  <link name="_Tibia__5__1">
    <inertial>
      <origin rpy="0 0 0" xyz="-0.0009218855506323564 -0.03197242771014009 0.02105715717094631"/>
      <mass value="0.07242936236987811"/>
      <inertia ixx="8.4e-05" ixy="-1e-06" ixz="-0.0" iyy="1.2e-05" iyz="-0.0" izz="8.1e-05"/>
    </inertial>
    <visual>
      <origin rpy="0 0 0" xyz="0.245483 -0.002786 0.051259"/>
      <geometry>
        <mesh filename="package://hapthexa_description/meshes/_Tibia__5__1.stl" scale="0.001 0.001 0.001"/>
      </geometry>
      <material name="_"/>
    </visual>
    <collision>
      <origin rpy="0 0 0" xyz="0.245483 -0.002786 0.051259"/>
      <geometry>
        <mesh filename="package://hapthexa_description/meshes/_Tibia__5__1.stl" scale="0.001 0.001 0.001"/>
      </geometry>
    </collision>
  </link>
  <link name="_Tibia__3__1">
    <inertial>
      <origin rpy="0 0 0" xyz="-0.018696308194575947 -0.03197242771013894 0.009729933485388115"/>
      <mass value="0.07242936236987811"/>
      <inertia ixx="8.2e-05" ixy="-0.0" ixz="1e-06" iyy="1.2e-05" iyz="-1e-06" izz="8.3e-05"/>
    </inertial>
    <visual>
      <origin rpy="0 0 0" xyz="0.11647 -0.002786 0.233116"/>
      <geometry>
        <mesh filename="package://hapthexa_description/meshes/_Tibia__3__1.stl" scale="0.001 0.001 0.001"/>
      </geometry>
      <material name="_"/>
    </visual>
    <collision>
      <origin rpy="0 0 0" xyz="0.11647 -0.002786 0.233116"/>
      <geometry>
        <mesh filename="package://hapthexa_description/meshes/_Tibia__3__1.stl" scale="0.001 0.001 0.001"/>
      </geometry>
    </collision>
  </link>
  <link name="_Tibia__4__1">
    <inertial>
      <origin rpy="0 0 0" xyz="-0.017774574194482445 -0.03197242771014097 -0.011326744486193502"/>
      <mass value="0.07242936236987811"/>
      <inertia ixx="8.2e-05" ixy="1e-06" ixz="-1e-06" iyy="1.2e-05" iyz="-1e-06" izz="8.3e-05"/>
    </inertial>
    <visual>
      <origin rpy="0 0 0" xyz="-0.10553 -0.002786 0.212316"/>
      <geometry>
        <mesh filename="package://hapthexa_description/meshes/_Tibia__4__1.stl" scale="0.001 0.001 0.001"/>
      </geometry>
      <material name="_"/>
    </visual>
    <collision>
      <origin rpy="0 0 0" xyz="-0.10553 -0.002786 0.212316"/>
      <geometry>
        <mesh filename="package://hapthexa_description/meshes/_Tibia__4__1.stl" scale="0.001 0.001 0.001"/>
      </geometry>
    </collision>
  </link>
  <link name="_Tibia__2__1">
    <inertial>
      <origin rpy="0 0 0" xyz="0.0009215824495506231 -0.031972427710139716 -0.021056198772232727"/>
      <mass value="0.07242936236987811"/>
      <inertia ixx="8.4e-05" ixy="1e-06" ixz="-0.0" iyy="1.2e-05" iyz="0.0" izz="8.1e-05"/>
    </inertial>
    <visual>
      <origin rpy="0 0 0" xyz="-0.198517 -0.002786 0.009659"/>
      <geometry>
        <mesh filename="package://hapthexa_description/meshes/_Tibia__2__1.stl" scale="0.001 0.001 0.001"/>
      </geometry>
      <material name="_"/>
    </visual>
    <collision>
      <origin rpy="0 0 0" xyz="-0.198517 -0.002786 0.009659"/>
      <geometry>
        <mesh filename="package://hapthexa_description/meshes/_Tibia__2__1.stl" scale="0.001 0.001 0.001"/>
      </geometry>
    </collision>
  </link>
  <link name="_Tibia__1__1">
    <inertial>
      <origin rpy="0 0 0" xyz="0.01865690897846689 -0.031972427710124596 -0.009804976119725611"/>
      <mass value="0.07242936236987811"/>
      <inertia ixx="8.2e-05" ixy="0.0" ixz="1e-06" iyy="1.2e-05" iyz="1e-06" izz="8.3e-05"/>
    </inertial>
    <visual>
      <origin rpy="0 0 0" xyz="-0.070041 -0.002786 -0.171984"/>
      <geometry>
        <mesh filename="package://hapthexa_description/meshes/_Tibia__1__1.stl" scale="0.001 0.001 0.001"/>
      </geometry>
      <material name="_"/>
    </visual>
    <collision>
      <origin rpy="0 0 0" xyz="-0.070041 -0.002786 -0.171984"/>
      <geometry>
        <mesh filename="package://hapthexa_description/meshes/_Tibia__1__1.stl" scale="0.001 0.001 0.001"/>
      </geometry>
    </collision>
  </link>
  <link name="_Tibia_1">
    <inertial>
      <origin rpy="0 0 0" xyz="0.017774271093425914 -0.0319724277101257 0.011326702884919576"/>
      <mass value="0.07242936236987811"/>
      <inertia ixx="8.2e-05" ixy="-1e-06" ixz="-1e-06" iyy="1.2e-05" iyz="1e-06" izz="8.3e-05"/>
    </inertial>
    <visual>
      <origin rpy="0 0 0" xyz="0.152496 -0.002686 -0.151399"/>
      <geometry>
        <mesh filename="package://hapthexa_description/meshes/_Tibia_1.stl" scale="0.001 0.001 0.001"/>
      </geometry>
      <material name="_"/>
    </visual>
    <collision>
      <origin rpy="0 0 0" xyz="0.152496 -0.002686 -0.151399"/>
      <geometry>
        <mesh filename="package://hapthexa_description/meshes/_Tibia_1.stl" scale="0.001 0.001 0.001"/>
      </geometry>
    </collision>
  </link>
  <joint name="rev1" type="continuous">
    <origin rpy="0 0 0" xyz="0.016517 0.026286 -0.099741"/>
    <parent link="base_link"/>
    <child link="_Coxa__4__1"/>
    <axis xyz="-0.0 1.0 -0.0"/>
  </joint>
  <joint name="rev2" type="continuous">
    <origin rpy="0 0 0" xyz="0.056517 0.026286 -0.030459"/>
    <parent link="base_link"/>
    <child link="_Coxa__2__1"/>
    <axis xyz="0.0 1.0 -0.0"/>
  </joint>
  <joint name="rev3" type="continuous">
    <origin rpy="0 0 0" xyz="0.016517 0.026286 0.038824"/>
    <parent link="base_link"/>
    <child link="_Coxa__1__1"/>
    <axis xyz="-0.0 1.0 0.0"/>
  </joint>
  <joint name="rev4" type="continuous">
    <origin rpy="0 0 0" xyz="-0.063483 0.026286 0.038824"/>
    <parent link="base_link"/>
    <child link="_Coxa_1"/>
    <axis xyz="0.0 1.0 0.0"/>
  </joint>
  <joint name="rev5" type="continuous">
    <origin rpy="0 0 0" xyz="-0.103483 0.026286 -0.030459"/>
    <parent link="base_link"/>
    <child link="_Coxa__5__1"/>
    <axis xyz="-0.0 1.0 -0.0"/>
  </joint>
  <joint name="rev6" type="continuous">
    <origin rpy="0 0 0" xyz="-0.063483 0.026286 -0.099741"/>
    <parent link="base_link"/>
    <child link="_Coxa__3__1"/>
    <axis xyz="0.0 1.0 -0.0"/>
  </joint>
  <joint name="rev7" type="continuous">
    <origin rpy="0 0 0" xyz="0.004903 -0.0235 0.045753"/>
    <parent link="_Coxa__1__1"/>
    <child link="_Femur__1__1"/>
    <axis xyz="-0.864003 -0.0 0.503487"/>
  </joint>
  <joint name="rev8" type="continuous">
    <origin rpy="0 0 0" xyz="-0.037281 -0.0236 0.026973"/>
    <parent link="_Coxa_1"/>
    <child link="_Femur_1"/>
    <axis xyz="-0.866025 0.0 -0.5"/>
  </joint>
  <joint name="rev9" type="continuous">
    <origin rpy="0 0 0" xyz="-0.042 -0.0235 -0.0188"/>
    <parent link="_Coxa__5__1"/>
    <child link="_Femur__5__1"/>
    <axis xyz="0.0 0.0 -1.0"/>
  </joint>
  <joint name="rev10" type="continuous">
    <origin rpy="0 0 0" xyz="-0.004719 -0.0235 -0.045773"/>
    <parent link="_Coxa__3__1"/>
    <child link="_Femur__3__1"/>
    <axis xyz="0.866025 -0.0 -0.5"/>
  </joint>
  <joint name="rev11" type="continuous">
    <origin rpy="0 0 0" xyz="0.037281 -0.0235 -0.026973"/>
    <parent link="_Coxa__4__1"/>
    <child link="_Femur__4__1"/>
    <axis xyz="0.866025 0.0 0.5"/>
  </joint>
  <joint name="rev12" type="continuous">
    <origin rpy="0 0 0" xyz="0.042 -0.0235 0.0188"/>
    <parent link="_Coxa__2__1"/>
    <child link="_Femur__2__1"/>
    <axis xyz="0.0 0.0 1.0"/>
  </joint>
  <joint name="rev13" type="continuous">
    <origin rpy="0 0 0" xyz="-0.1 0.0 -0.002"/>
    <parent link="_Femur__5__1"/>
    <child link="_Tibia__5__1"/>
    <axis xyz="-0.0 -0.0 1.0"/>
  </joint>
  <joint name="rev14" type="continuous">
    <origin rpy="0 0 0" xyz="-0.048268 0.0 -0.087602"/>
    <parent link="_Femur__3__1"/>
    <child link="_Tibia__3__1"/>
    <axis xyz="-0.866025 0.0 0.5"/>
  </joint>
  <joint name="rev15" type="continuous">
    <origin rpy="0 0 0" xyz="0.051732 0.0 -0.085602"/>
    <parent link="_Femur__4__1"/>
    <child link="_Tibia__4__1"/>
    <axis xyz="-0.866025 -0.0 -0.5"/>
  </joint>
  <joint name="rev16" type="continuous">
    <origin rpy="0 0 0" xyz="0.1 0.0 0.002"/>
    <parent link="_Femur__2__1"/>
    <child link="_Tibia__2__1"/>
    <axis xyz="-0.0 -0.0 -1.0"/>
  </joint>
  <joint name="rev17" type="continuous">
    <origin rpy="0 0 0" xyz="0.048621 0.0 0.087407"/>
    <parent link="_Femur__1__1"/>
    <child link="_Tibia__1__1"/>
    <axis xyz="0.864003 0.0 -0.503487"/>
  </joint>
  <joint name="rev18" type="continuous">
    <origin rpy="0 0 0" xyz="-0.051732 0.0 0.085602"/>
    <parent link="_Femur_1"/>
    <child link="_Tibia_1"/>
    <axis xyz="0.866025 -0.0 0.5"/>
  </joint>
</robot>
